<?xml version="1.0"?>

<robot name="sentry_robot" xmlns:xacro="http://www.ros.org/wiki/xacro">

  <xacro:property name="length_wheel" value="0.05" />
  <xacro:property name="radius_wheel" value="0.06" />
  <xacro:property name="PI" value="3.1415926"/>
  <xacro:macro name="default_inertial" params="mass">
    <inertial>
      <mass value="${mass}" />
      <inertia ixx="0.01" ixy="0.0" ixz="0.0"
                    iyy="0.01" iyz="0.0" izz="0.01" />
    </inertial>
  </xacro:macro>

  <!-- base_link to livox_frame -->
  <xacro:arg name="xyz" default="0.12 0.0 0.175" />
  <xacro:arg name="rpy" default="0 0 0" />


  <!-- base link -->
  <link name="base_link">
    <visual>
      <origin xyz="0 0 0.0" rpy="0 0 0"/>
      <geometry>
        <cylinder length="0.12" radius="0.10"/>
      </geometry>
      <material name="blue">
        <color rgba="0.1 0.1 1.0 0.5" />
      </material>
    </visual>
    <collision>
      <origin xyz="0 0 0.0" rpy="0 0 0"/>
      <geometry>
        <cylinder length="0.12" radius="0.10"/>
      </geometry>
      <material name="blue">
        <color rgba="0.1 0.1 1.0 0.5" />
      </material>
    </collision>
    <inertial>
      <mass value="0.2"/>
      <inertia ixx="0.0122666" ixy="0" ixz="0" iyy="0.0122666" iyz="0" izz="0.02"/>
    </inertial>
  </link>

  <!-- IMU joint -->
  <joint name="imu_joint" type="fixed">
    <axis xyz="0 1 0" />
    <origin xyz="0 0 0.085" rpy="0 0 0"/>
    <parent link="base_link"/>
    <child link="imu_link"/>
  </joint>

  <!-- IMU -->
  <link name="imu_link">
    <collision>
      <origin xyz="0 0 0" rpy="0 0 0"/>
      <geometry>
        <box size="0.05 0.05 0.05"/>
      </geometry>
    </collision>
    <visual>
      <origin xyz="0 0 0" rpy="0 0 0"/>
      <geometry>
        <box size="0.05 0.05 0.05"/>
      </geometry>
      <material name="green">
        <color rgba="0 1 0 1"/>
      </material>
    </visual>
    <inertial>
      <mass value="1e-2" />
      <origin xyz="0 0 0" rpy="0 0 0"/>
      <inertia ixx="1e-6" ixy="0" ixz="0" iyy="1e-6" iyz="0" izz="1e-6" />
    </inertial>
  </link> <link name="left_wheel_link">
  <visual>
    <origin xyz="0 0 0" rpy="1.57079 0 0"/>
    <geometry>
      <cylinder length="0.04" radius="0.032"/>
    </geometry>
    <material name="black">
      <color rgba="0.0 0.0 0.0 0.5" />
    </material>
  </visual>
  <collision>
    <origin xyz="0 0 0" rpy="1.57079 0 0"/>
    <geometry>
      <cylinder length="0.04" radius="0.032"/>
    </geometry>
    <material name="black">
      <color rgba="0.0 0.0 0.0 0.5" />
    </material>
  </collision>
  <inertial>
    <mass value="0.2"/>
    <inertia ixx="0.000190416666667" ixy="0" ixz="0" iyy="0.0001904" iyz="0" izz="0.00036"/>
  </inertial>
</link>

  <link name="right_wheel_link">
    <visual>
      <origin xyz="0 0 0" rpy="1.57079 0 0"/>
      <geometry>
        <cylinder length="0.04" radius="0.032"/>
      </geometry>
      <material name="black">
        <color rgba="0.0 0.0 0.0 0.5" />
      </material>
    </visual>
    <collision>
      <origin xyz="0 0 0" rpy="1.57079 0 0"/>
      <geometry>
        <cylinder length="0.04" radius="0.032"/>
      </geometry>
      <material name="black">
        <color rgba="0.0 0.0 0.0 0.5" />
      </material>
    </collision>
    <inertial>
      <mass value="0.2"/>
      <inertia ixx="0.000190416666667" ixy="0" ixz="0" iyy="0.0001904" iyz="0" izz="0.00036"/>
    </inertial>
  </link>

  <joint name="left_wheel_joint" type="continuous">
    <parent link="base_link" />
    <child link="left_wheel_link" />
    <origin xyz="-0.02 0.10 -0.06" />
    <axis xyz="0 1 0" />
  </joint>

  <joint name="right_wheel_joint" type="continuous">
    <parent link="base_link" />
    <child link="right_wheel_link" />
    <origin xyz="-0.02 -0.10 -0.06" />
    <axis xyz="0 1 0" />
  </joint>

  <link name="caster_link">
    <visual>
      <origin xyz="0 0 0" rpy="1.57079 0 0"/>
      <geometry>
        <sphere radius="0.016"/>
      </geometry>
      <material name="black">
        <color rgba="0.0 0.0 0.0 0.5" />
      </material>
    </visual>
    <collision>
      <origin xyz="0 0 0" rpy="1.57079 0 0"/>
      <geometry>
        <sphere radius="0.016"/>
      </geometry>
      <material name="black">
        <color rgba="0.0 0.0 0.0 0.5" />
      </material>
    </collision>
    <inertial>
      <mass value="0.02"/>
      <inertia ixx="0.000190416666667" ixy="0" ixz="0" iyy="0.0001904" iyz="0" izz="0.00036"/>
    </inertial>
  </link>

  <joint name="caster_joint" type="fixed">
    <parent link="base_link" />
    <child link="caster_link" />
    <origin xyz="0.06 0.0 -0.076" />
    <axis xyz="0 1 0" />
  </joint>



  <gazebo reference="caster_link">
    <material>Gazebo/Black</material>
  </gazebo>

  <gazebo reference="caster_link">
    <mu1 value="0.0"/>
    <mu2 value="0.0"/>
    <kp value="1000000.0" />
    <kd value="10.0" />
  </gazebo>

  <!-- Gazebo插件设置相关 -->
  <gazebo reference="base_link">
    <material>Gazebo/Orange</material>
  </gazebo>
  <gazebo reference="imu_link">
    <material>Gazebo/BuildingFrame</material>
  </gazebo>
  <gazebo reference="livox_frame">
    <material>Gazebo/LightBlueLaser</material>
  </gazebo>

  <!-- Drive controller plugin-->
  <!-- https://github.com/ros-simulation/gazebo_ros_pkgs/wiki/ROS-2-Migration:-Planar-Move -->
<!--  <gazebo>-->
<!--    <plugin name="mecanum_controller" filename="libgazebo_ros_planar_move.so">-->
<!--      <ros>-->
<!--        &lt;!&ndash; Add a namespace &ndash;&gt;-->
<!--        <namespace>/</namespace>-->
<!--        &lt;!&ndash; Remap the default topic &ndash;&gt;-->
<!--        <remapping>cmd_vel:=cmd_vel_chassis</remapping>-->
<!--        <remapping>odom:=odom</remapping>-->
<!--      </ros>-->

<!--      &lt;!&ndash; Set control loop update rate &ndash;&gt;-->
<!--      <update_rate>100</update_rate>-->
<!--      &lt;!&ndash; Set odom publish rate &ndash;&gt;-->
<!--      <publish_rate>10</publish_rate>-->

<!--      &lt;!&ndash; Set if odom required &ndash;&gt;-->
<!--      <publish_odom>false</publish_odom>-->
<!--      <publish_odom_tf>false</publish_odom_tf>-->

<!--      &lt;!&ndash; Frame IDs &ndash;&gt;-->
<!--      <odometry_frame>odom</odometry_frame>-->
<!--      <robot_base_frame>base_link</robot_base_frame>-->

<!--      &lt;!&ndash; Set odom covariance &ndash;&gt;-->
<!--      <covariance_x>0.0001</covariance_x>-->
<!--      <covariance_y>0.0001</covariance_y>-->
<!--      <covariance_yaw>0.01</covariance_yaw>-->
<!--    </plugin>-->
<!--  </gazebo>-->
  <gazebo>
    <plugin name='diff_drive' filename='libgazebo_ros_diff_drive.so'>
      <ros>
        <namespace>/</namespace>
        <remapping>cmd_vel:=cmd_vel</remapping>
        <remapping>odom:=diff_odom</remapping>
      </ros>
      <update_rate>100</update_rate>
      <!-- wheels -->
      <left_joint>left_wheel_joint</left_joint>
      <right_joint>right_wheel_joint</right_joint>
      <!-- kinematics -->
      <wheel_separation>0.2</wheel_separation>
      <wheel_diameter>0.065</wheel_diameter>
      <!-- limits -->
      <max_wheel_torque>20</max_wheel_torque>
      <max_wheel_acceleration>1.0</max_wheel_acceleration>
      <!-- output -->
      <publish_odom>false</publish_odom>
      <publish_odom_tf>false</publish_odom_tf>
      <publish_wheel_tf>false</publish_wheel_tf>
      <odometry_frame>diff_odom</odometry_frame>
      <robot_base_frame>base_link</robot_base_frame>
    </plugin>
  </gazebo>

  <!-- mid360_imu plugin -->
  <!-- https://github.com/ros-simulation/gazebo_ros_pkgs/wiki/ROS-2-Migration:-IMU-Sensors -->
  <gazebo reference="imu_link">
    <sensor name="mid360_imu" type="imu">
      <always_on>true</always_on>
      <update_rate>100</update_rate>
      <plugin name="imu_plugin" filename="libgazebo_ros_imu_sensor.so">
        <ros>
          <namespace>/</namespace>
          <remapping>~/out:=/livox/imu</remapping>
        </ros>
        <frame_name>imu_link</frame_name>
      </plugin>
    </sensor>
  </gazebo>

  <!-- Livox-Mid360  -->
  <xacro:include filename="$(find hunter_robot)/urdf/mid360.xacro" />
  <xacro:mid360 name="livox_frame" parent="base_link" topic="/livox/lidar">
    <origin xyz="0 0 0.135" rpy="0 0 0" />
  </xacro:mid360>

</robot>
